#VRML_SIM R2023b utf8

EXTERNPROTO "https://raw.githubusercontent.com/cyberbotics/webots/R2023b/projects/objects/backgrounds/protos/TexturedBackground.proto"
EXTERNPROTO "https://raw.githubusercontent.com/cyberbotics/webots/R2023b/projects/objects/backgrounds/protos/TexturedBackgroundLight.proto"
EXTERNPROTO "https://raw.githubusercontent.com/cyberbotics/webots/R2023b/projects/objects/floors/protos/RectangleArena.proto"
EXTERNPROTO "https://raw.githubusercontent.com/cyberbotics/webots/R2023b/projects/appearances/protos/Parquetry.proto"
IMPORTABLE EXTERNPROTO "../protos/Pioneer2F8.proto"
IMPORTABLE EXTERNPROTO "../protos/Pioneer2FB.proto"
IMPORTABLE EXTERNPROTO "../protos/Pioneer2FB6.proto"
IMPORTABLE EXTERNPROTO "../protos/Pioneer2LR.proto"

WorldInfo {
}
Viewpoint {
  orientation -0.01054730811230908 -0.8906874942270466 -0.45449372043970904 6.143362293758805
  position -5.239379654912478 -0.6592245766160988 0.7755173296338688
}
TexturedBackground {
}
TexturedBackgroundLight {
}
RectangleArena {
  floorSize 30 30
  floorAppearance Parquetry {
    type "light strip"
  }
  wallHeight 0.4
}
DEF PIONEER2 Robot {
  translation -1.5 -0.5 0
  rotation 0 0 1 2.61799
  children [
    Group {
    }
    Shape {
      appearance PBRAppearance {
        baseColor 1 0 0
        roughness 0.3
        metalness 0
      }
      geometry IndexedFaceSet {
        coord Coordinate {
          point [
            -0.215 0.1 0.059
            -0.215 -0.1 0.059
            -0.185 -0.135 0.059
            0.095 -0.135 0.059
            0.11 -0.08 0.059
            0.11 0.08 0.059
            0.095 0.135 0.059
            -0.185 0.135 0.059
            -0.215 0.1 0.059
            -0.215 0.1 0.234
            -0.215 -0.1 0.234
            -0.185 -0.135 0.234
            0.095 -0.135 0.234
            0.11 -0.08 0.234
            0.11 0.08 0.234
            0.095 0.135 0.234
            -0.185 0.135 0.234
            -0.215 0.1 0.234
          ]
        }
        coordIndex [
          8, 7, 6, 5, 4, 3, 2, 1, 0, -1, 9, 10, 11, 12, 13, 14, 15, 16, 17, -1, 0, 1, 10, 9, -1, 1, 2, 11, 10, -1, 2, 3, 12, 11, -1, 3, 4, 13, 12, -1, 4, 5, 14, 13, -1, 5, 6, 15, 14, -1, 6, 7, 16, 15, -1, 7, 8, 17, 16, -1
        ]
      }
    }
    HingeJoint {
      jointParameters HingeJointParameters {
        axis 0 1 0
        anchor 0 0 0.0825
      }
      device [
        RotationalMotor {
          name "left wheel motor"
        }
        PositionSensor {
          name "left wheel sensor"
        }
      ]
      endPoint Solid {
        translation 0 0.1603 0.0825
        rotation -0.25268397011342625 0.25268397011342625 0.9339708895331987 -1.639053
        children [
          DEF WHEEL Pose {
            rotation 0.577656895078166 0.5771968951617173 -0.5771968951617173 -2.093935
            children [
              Shape {
                appearance PBRAppearance {
                  baseColor 0.0037037 0.0037037 0.0037037
                  roughness 0.3
                  metalness 0
                }
                geometry Cylinder {
                  height 0.037
                  radius 0.0825
                }
              }
            ]
          }
        ]
        name "left wheel"
        boundingObject USE WHEEL
      }
    }
    HingeJoint {
      jointParameters HingeJointParameters {
        axis 0 1 0
        anchor 0 0 0.0825
      }
      device [
        RotationalMotor {
          name "right wheel motor"
        }
        PositionSensor {
          name "right wheel sensor"
        }
      ]
      endPoint Solid {
        translation 0 -0.1603 0.0825
        rotation 0.6879677669702214 -0.6879677669702214 -0.23108592172612766 2.687394
        children [
          USE WHEEL
        ]
        name "right wheel"
        boundingObject USE WHEEL
      }
    }
    Shape {
      appearance PBRAppearance {
        baseColor 1 0 0
        roughness 0.3
        metalness 0
      }
      geometry IndexedFaceSet {
        coord Coordinate {
          point [
            0.046 -0.136 0.184
            0.096 -0.136 0.184
            0.134 -0.101 0.184
            0.159 -0.054 0.184
            0.168 0 0.184
            0.159 0.054 0.184
            0.134 0.101 0.184
            0.096 0.136 0.184
            0.046 0.136 0.184
            0.043 -0.136 0.184
            0.046 -0.136 0.234
            0.096 -0.136 0.234
            0.134 -0.101 0.234
            0.159 -0.054 0.234
            0.168 0 0.234
            0.159 0.054 0.234
            0.134 0.101 0.234
            0.096 0.136 0.234
            0.046 0.136 0.234
            0.043 -0.136 0.234
          ]
        }
        coordIndex [
          9, 8, 7, 6, 5, 4, 3, 2, 1, 0, -1, 10, 11, 12, 13, 14, 15, 16, 17, 18, 19, -1, 0, 1, 11, 10, -1, 1, 2, 12, 11, -1, 2, 3, 13, 12, -1, 3, 4, 14, 13, -1, 4, 5, 15, 14, -1, 5, 6, 16, 15, -1, 6, 7, 17, 16, -1, 7, 8, 18, 17, -1, 8, 9, 19, 18, -1, 9, 0, 10, 19, -1
        ]
      }
    }
    Shape {
      appearance PBRAppearance {
        baseColor 1 0 0
        roughness 0.3
        metalness 0
      }
      geometry IndexedFaceSet {
        coord Coordinate {
          point [
            -0.135 0.136 0.184
            -0.185 0.136 0.184
            -0.223 0.101 0.184
            -0.248 0.054 0.184
            -0.257 0 0.184
            -0.248 -0.054 0.184
            -0.223 -0.101 0.184
            -0.185 -0.136 0.184
            -0.135 -0.136 0.184
            -0.135 0.136 0.184
            -0.135 0.136 0.234
            -0.185 0.136 0.234
            -0.223 0.101 0.234
            -0.248 0.054 0.234
            -0.257 0 0.234
            -0.248 -0.054 0.234
            -0.223 -0.101 0.234
            -0.185 -0.136 0.234
            -0.135 -0.136 0.234
            -0.135 0.136 0.234
          ]
        }
        coordIndex [
          9, 8, 7, 6, 5, 4, 3, 2, 1, 0, -1, 10, 11, 12, 13, 14, 15, 16, 17, 18, 19, -1, 0, 1, 11, 10, -1, 1, 2, 12, 11, -1, 2, 3, 13, 12, -1, 3, 4, 14, 13, -1, 4, 5, 15, 14, -1, 5, 6, 16, 15, -1, 6, 7, 17, 16, -1, 7, 8, 18, 17, -1, 8, 9, 19, 18, -1
        ]
      }
    }
    Pose {
      translation -0.2147 0 0.0325
      rotation 0.5771968951617173 0.5771968951617173 0.577656895078166 -2.093935
      children [
        Shape {
          appearance PBRAppearance {
            baseColor 0.0037037 0.0037037 0.0037037
            roughness 0.3
            metalness 0
          }
          geometry Cylinder {
            height 0.024
            radius 0.0325
          }
        }
      ]
    }
    DistanceSensor {
      translation 0.071 0.136 0.209
      rotation 0.5779627730800116 0.5770437734408297 0.5770437734408297 2.093476
      children [
        DEF SONAR Pose {
          rotation 0.577656895078166 0.5771968951617173 -0.5771968951617173 -2.093935
          children [
            Shape {
              appearance PBRAppearance {
                baseColor 1 1 0.0517103
                roughness 0.3
                metalness 0
              }
              geometry Cylinder {
                height 0.002
                radius 0.0175
              }
            }
          ]
        }
      ]
      name "ds0"
      lookupTable [
        0 1024 0
        0.2 1024 0.1
        0.4 0 0.1
      ]
      type "sonar"
      numberOfRays 5
    }
    DistanceSensor {
      translation 0.116 0.118 0.209
      rotation 0.8349694730900802 0.38911822047269523 0.38911822047269523 1.750187
      children [
        USE SONAR
      ]
      name "ds1"
      lookupTable [
        0 1024 0
        0.2 1024 0.1
        0.4 0 0.1
      ]
      type "sonar"
      numberOfRays 5
    }
    DistanceSensor {
      translation 0.147 0.077 0.209
      rotation 0.9352057350394192 0.25038992906003615 0.25038992906003615 1.637735
      children [
        USE SONAR
      ]
      name "ds2"
      lookupTable [
        0 1024 0
        0.2 1024 0.1
        0.4 0 0.1
      ]
      type "sonar"
      numberOfRays 5
    }
    DistanceSensor {
      translation 0.164 0.027 0.209
      rotation 0 0 1 0.174203
      children [
        USE SONAR
      ]
      name "ds3"
      lookupTable [
        0 1024 0
        0.2 1024 0.1
        0.4 0 0.1
      ]
      type "sonar"
      numberOfRays 5
    }
    DistanceSensor {
      translation 0.164 -0.027 0.209
      rotation -0.9924098511524273 0.08695598695782032 0.08695598695782032 -1.578415
      children [
        USE SONAR
      ]
      name "ds4"
      lookupTable [
        0 1024 0
        0.2 1024 0.1
        0.4 0 0.1
      ]
      type "sonar"
      numberOfRays 5
    }
    DistanceSensor {
      translation 0.147 -0.077 0.209
      rotation 0.9350669359988784 -0.25064898284420567 -0.25064898284420567 1.637883
      children [
        USE SONAR
      ]
      name "ds5"
      lookupTable [
        0 1024 0
        0.2 1024 0.1
        0.4 0 0.1
      ]
      type "sonar"
      numberOfRays 5
    }
    DistanceSensor {
      translation 0.116 -0.118 0.209
      rotation 0.8347739105773538 -0.38932795829441263 -0.38932795829441263 1.750417
      children [
        USE SONAR
      ]
      name "ds6"
      lookupTable [
        0 1024 0
        0.2 1024 0.1
        0.4 0 0.1
      ]
      type "sonar"
      numberOfRays 5
    }
    DistanceSensor {
      translation 0.071 -0.136 0.209
      rotation 0.5773502691896258 -0.5773502691896258 -0.5773502691896258 2.094395
      children [
        USE SONAR
      ]
      name "ds7"
      lookupTable [
        0 1024 0
        0.2 1024 0.1
        0.4 0 0.1
      ]
      type "sonar"
      numberOfRays 5
    }
  ]
  name "Pioneer 2(1)"
  description "designed by Activmedia Robotics"
  boundingObject Pose {
    translation -0.0447 0 0.13
    rotation 0 0 1 -1.570796
    children [
      Cylinder {
        height 0.24
        radius 0.219
      }
    ]
  }
  controller "rl"
  supervisor TRUE
}
DEF PIONEER2 Robot {
  translation -0.8 0.3 0
  rotation 0 0 1 -1.3089953071795861
  children [
    Group {
    }
    Shape {
      appearance PBRAppearance {
        baseColor 1 0 0
        roughness 0.3
        metalness 0
      }
      geometry IndexedFaceSet {
        coord Coordinate {
          point [
            -0.215 0.1 0.059
            -0.215 -0.1 0.059
            -0.185 -0.135 0.059
            0.095 -0.135 0.059
            0.11 -0.08 0.059
            0.11 0.08 0.059
            0.095 0.135 0.059
            -0.185 0.135 0.059
            -0.215 0.1 0.059
            -0.215 0.1 0.234
            -0.215 -0.1 0.234
            -0.185 -0.135 0.234
            0.095 -0.135 0.234
            0.11 -0.08 0.234
            0.11 0.08 0.234
            0.095 0.135 0.234
            -0.185 0.135 0.234
            -0.215 0.1 0.234
          ]
        }
        coordIndex [
          8, 7, 6, 5, 4, 3, 2, 1, 0, -1, 9, 10, 11, 12, 13, 14, 15, 16, 17, -1, 0, 1, 10, 9, -1, 1, 2, 11, 10, -1, 2, 3, 12, 11, -1, 3, 4, 13, 12, -1, 4, 5, 14, 13, -1, 5, 6, 15, 14, -1, 6, 7, 16, 15, -1, 7, 8, 17, 16, -1
        ]
      }
    }
    HingeJoint {
      jointParameters HingeJointParameters {
        axis 0 1 0
        anchor 0 0 0.0825
      }
      device [
        RotationalMotor {
          name "left wheel motor"
        }
        PositionSensor {
          name "left wheel sensor"
        }
      ]
      endPoint Solid {
        translation 0 0.1603 0.0825
        rotation -0.25268397011342625 0.25268397011342625 0.9339708895331987 -1.639053
        children [
          DEF WHEEL Pose {
            rotation 0.577656895078166 0.5771968951617173 -0.5771968951617173 -2.093935
            children [
              Shape {
                appearance PBRAppearance {
                  baseColor 0.0037037 0.0037037 0.0037037
                  roughness 0.3
                  metalness 0
                }
                geometry Cylinder {
                  height 0.037
                  radius 0.0825
                }
              }
            ]
          }
        ]
        name "left wheel"
        boundingObject USE WHEEL
      }
    }
    HingeJoint {
      jointParameters HingeJointParameters {
        axis 0 1 0
        anchor 0 0 0.0825
      }
      device [
        RotationalMotor {
          name "right wheel motor"
        }
        PositionSensor {
          name "right wheel sensor"
        }
      ]
      endPoint Solid {
        translation 0 -0.1603 0.0825
        rotation 0.6879677669702214 -0.6879677669702214 -0.23108592172612766 2.687394
        children [
          USE WHEEL
        ]
        name "right wheel"
        boundingObject USE WHEEL
      }
    }
    Shape {
      appearance PBRAppearance {
        baseColor 1 0 0
        roughness 0.3
        metalness 0
      }
      geometry IndexedFaceSet {
        coord Coordinate {
          point [
            0.046 -0.136 0.184
            0.096 -0.136 0.184
            0.134 -0.101 0.184
            0.159 -0.054 0.184
            0.168 0 0.184
            0.159 0.054 0.184
            0.134 0.101 0.184
            0.096 0.136 0.184
            0.046 0.136 0.184
            0.043 -0.136 0.184
            0.046 -0.136 0.234
            0.096 -0.136 0.234
            0.134 -0.101 0.234
            0.159 -0.054 0.234
            0.168 0 0.234
            0.159 0.054 0.234
            0.134 0.101 0.234
            0.096 0.136 0.234
            0.046 0.136 0.234
            0.043 -0.136 0.234
          ]
        }
        coordIndex [
          9, 8, 7, 6, 5, 4, 3, 2, 1, 0, -1, 10, 11, 12, 13, 14, 15, 16, 17, 18, 19, -1, 0, 1, 11, 10, -1, 1, 2, 12, 11, -1, 2, 3, 13, 12, -1, 3, 4, 14, 13, -1, 4, 5, 15, 14, -1, 5, 6, 16, 15, -1, 6, 7, 17, 16, -1, 7, 8, 18, 17, -1, 8, 9, 19, 18, -1, 9, 0, 10, 19, -1
        ]
      }
    }
    Shape {
      appearance PBRAppearance {
        baseColor 1 0 0
        roughness 0.3
        metalness 0
      }
      geometry IndexedFaceSet {
        coord Coordinate {
          point [
            -0.135 0.136 0.184
            -0.185 0.136 0.184
            -0.223 0.101 0.184
            -0.248 0.054 0.184
            -0.257 0 0.184
            -0.248 -0.054 0.184
            -0.223 -0.101 0.184
            -0.185 -0.136 0.184
            -0.135 -0.136 0.184
            -0.135 0.136 0.184
            -0.135 0.136 0.234
            -0.185 0.136 0.234
            -0.223 0.101 0.234
            -0.248 0.054 0.234
            -0.257 0 0.234
            -0.248 -0.054 0.234
            -0.223 -0.101 0.234
            -0.185 -0.136 0.234
            -0.135 -0.136 0.234
            -0.135 0.136 0.234
          ]
        }
        coordIndex [
          9, 8, 7, 6, 5, 4, 3, 2, 1, 0, -1, 10, 11, 12, 13, 14, 15, 16, 17, 18, 19, -1, 0, 1, 11, 10, -1, 1, 2, 12, 11, -1, 2, 3, 13, 12, -1, 3, 4, 14, 13, -1, 4, 5, 15, 14, -1, 5, 6, 16, 15, -1, 6, 7, 17, 16, -1, 7, 8, 18, 17, -1, 8, 9, 19, 18, -1
        ]
      }
    }
    Pose {
      translation -0.2147 0 0.0325
      rotation 0.5771968951617173 0.5771968951617173 0.577656895078166 -2.093935
      children [
        Shape {
          appearance PBRAppearance {
            baseColor 0.0037037 0.0037037 0.0037037
            roughness 0.3
            metalness 0
          }
          geometry Cylinder {
            height 0.024
            radius 0.0325
          }
        }
      ]
    }
    DistanceSensor {
      translation 0.071 0.136 0.209
      rotation 0.5779627730800116 0.5770437734408297 0.5770437734408297 2.093476
      children [
        DEF SONAR Pose {
          rotation 0.577656895078166 0.5771968951617173 -0.5771968951617173 -2.093935
          children [
            Shape {
              appearance PBRAppearance {
                baseColor 1 1 0.0517103
                roughness 0.3
                metalness 0
              }
              geometry Cylinder {
                height 0.002
                radius 0.0175
              }
            }
          ]
        }
      ]
      name "ds0"
      lookupTable [
        0 1024 0
        0.2 1024 0.1
        0.4 0 0.1
      ]
      type "sonar"
      numberOfRays 5
    }
    DistanceSensor {
      translation 0.116 0.118 0.209
      rotation 0.8349694730900802 0.38911822047269523 0.38911822047269523 1.750187
      children [
        USE SONAR
      ]
      name "ds1"
      lookupTable [
        0 1024 0
        0.2 1024 0.1
        0.4 0 0.1
      ]
      type "sonar"
      numberOfRays 5
    }
    DistanceSensor {
      translation 0.147 0.077 0.209
      rotation 0.9352057350394192 0.25038992906003615 0.25038992906003615 1.637735
      children [
        USE SONAR
      ]
      name "ds2"
      lookupTable [
        0 1024 0
        0.2 1024 0.1
        0.4 0 0.1
      ]
      type "sonar"
      numberOfRays 5
    }
    DistanceSensor {
      translation 0.164 0.027 0.209
      rotation 0 0 1 0.174203
      children [
        USE SONAR
      ]
      name "ds3"
      lookupTable [
        0 1024 0
        0.2 1024 0.1
        0.4 0 0.1
      ]
      type "sonar"
      numberOfRays 5
    }
    DistanceSensor {
      translation 0.164 -0.027 0.209
      rotation -0.9924098511524273 0.08695598695782032 0.08695598695782032 -1.578415
      children [
        USE SONAR
      ]
      name "ds4"
      lookupTable [
        0 1024 0
        0.2 1024 0.1
        0.4 0 0.1
      ]
      type "sonar"
      numberOfRays 5
    }
    DistanceSensor {
      translation 0.147 -0.077 0.209
      rotation 0.9350669359988784 -0.25064898284420567 -0.25064898284420567 1.637883
      children [
        USE SONAR
      ]
      name "ds5"
      lookupTable [
        0 1024 0
        0.2 1024 0.1
        0.4 0 0.1
      ]
      type "sonar"
      numberOfRays 5
    }
    DistanceSensor {
      translation 0.116 -0.118 0.209
      rotation 0.8347739105773538 -0.38932795829441263 -0.38932795829441263 1.750417
      children [
        USE SONAR
      ]
      name "ds6"
      lookupTable [
        0 1024 0
        0.2 1024 0.1
        0.4 0 0.1
      ]
      type "sonar"
      numberOfRays 5
    }
    DistanceSensor {
      translation 0.071 -0.136 0.209
      rotation 0.5773502691896258 -0.5773502691896258 -0.5773502691896258 2.094395
      children [
        USE SONAR
      ]
      name "ds7"
      lookupTable [
        0 1024 0
        0.2 1024 0.1
        0.4 0 0.1
      ]
      type "sonar"
      numberOfRays 5
    }
    DistanceSensor {
      translation -0.16 0.136 0.209
      rotation -0.5767367732078247 -0.5776567728460501 -0.5776567728460501 -2.095315
      children [
        USE SONAR
      ]
      name "ds8"
      lookupTable [
        0 1024 0
        0.2 1024 0.1
        0.4 0 0.1
      ]
      type "sonar"
      numberOfRays 5
    }
    DistanceSensor {
      translation -0.205 0.118 0.209
      rotation -0.31297577647997865 -0.6715825203713816 -0.6715825203713816 -2.534956
      children [
        USE SONAR
      ]
      name "ds9"
      lookupTable [
        0 1024 0
        0.2 1024 0.1
        0.4 0 0.1
      ]
      type "sonar"
      numberOfRays 5
    }
    DistanceSensor {
      translation -0.236 0.077 0.209
      rotation -0.1860148912057814 -0.6947655936536081 -0.6947655936536081 -2.773767
      children [
        USE SONAR
      ]
      name "ds10"
      lookupTable [
        0 1024 0
        0.2 1024 0.1
        0.4 0 0.1
      ]
      type "sonar"
      numberOfRays 5
    }
    DistanceSensor {
      translation -0.253 0.027 0.209
      rotation -0.06162897048037732 -0.7057626619471765 -0.7057626619471765 -3.01849
      children [
        USE SONAR
      ]
      name "ds11"
      lookupTable [
        0 1024 0
        0.2 1024 0.1
        0.4 0 0.1
      ]
      type "sonar"
      numberOfRays 5
    }
    DistanceSensor {
      translation -0.253 -0.027 0.209
      rotation -0.06183904155773597 0.7057534742880195 0.7057534742880195 -3.018072
      children [
        USE SONAR
      ]
      name "ds12"
      lookupTable [
        0 1024 0
        0.2 1024 0.1
        0.4 0 0.1
      ]
      type "sonar"
      numberOfRays 5
    }
    DistanceSensor {
      translation -0.236 -0.077 0.209
      rotation -0.1862280124472945 0.6947370464355309 0.6947370464355309 -2.773355
      children [
        USE SONAR
      ]
      name "ds13"
      lookupTable [
        0 1024 0
        0.2 1024 0.1
        0.4 0 0.1
      ]
      type "sonar"
      numberOfRays 5
    }
    DistanceSensor {
      translation -0.205 -0.118 0.209
      rotation -0.31319385347479545 0.6715316858293465 0.6715316858293465 -2.534558
      children [
        USE SONAR
      ]
      name "ds14"
      lookupTable [
        0 1024 0
        0.2 1024 0.1
        0.4 0 0.1
      ]
      type "sonar"
      numberOfRays 5
    }
    DistanceSensor {
      translation -0.16 -0.136 0.209
      rotation 0.5773502691896258 -0.5773502691896258 -0.5773502691896258 2.094395
      children [
        USE SONAR
      ]
      name "ds15"
      lookupTable [
        0 1024 0
        0.2 1024 0.1
        0.4 0 0.1
      ]
      type "sonar"
      numberOfRays 5
    }
  ]
  name "Pioneer 2"
  description "designed by Activmedia Robotics"
  boundingObject Pose {
    translation -0.0447 0 0.13
    rotation 0 0 1 -1.570796
    children [
      Cylinder {
        height 0.24
        radius 0.219
      }
    ]
  }
  controller "<none>"
}
DEF PIONEER2 Robot {
  translation -0.5 -1 0
  rotation 0 0 1 0.9163003061004252
  children [
    Group {
    }
    Shape {
      appearance PBRAppearance {
        baseColor 1 0 0
        roughness 0.3
        metalness 0
      }
      geometry IndexedFaceSet {
        coord Coordinate {
          point [
            -0.215 0.1 0.059
            -0.215 -0.1 0.059
            -0.185 -0.135 0.059
            0.095 -0.135 0.059
            0.11 -0.08 0.059
            0.11 0.08 0.059
            0.095 0.135 0.059
            -0.185 0.135 0.059
            -0.215 0.1 0.059
            -0.215 0.1 0.234
            -0.215 -0.1 0.234
            -0.185 -0.135 0.234
            0.095 -0.135 0.234
            0.11 -0.08 0.234
            0.11 0.08 0.234
            0.095 0.135 0.234
            -0.185 0.135 0.234
            -0.215 0.1 0.234
          ]
        }
        coordIndex [
          8, 7, 6, 5, 4, 3, 2, 1, 0, -1, 9, 10, 11, 12, 13, 14, 15, 16, 17, -1, 0, 1, 10, 9, -1, 1, 2, 11, 10, -1, 2, 3, 12, 11, -1, 3, 4, 13, 12, -1, 4, 5, 14, 13, -1, 5, 6, 15, 14, -1, 6, 7, 16, 15, -1, 7, 8, 17, 16, -1
        ]
      }
    }
    HingeJoint {
      jointParameters HingeJointParameters {
        axis 0 1 0
        anchor 0 0 0.0825
      }
      device [
        RotationalMotor {
          name "left wheel motor"
        }
        PositionSensor {
          name "left wheel sensor"
        }
      ]
      endPoint Solid {
        translation 0 0.1603 0.0825
        rotation -0.25268397011342625 0.25268397011342625 0.9339708895331987 -1.639053
        children [
          DEF WHEEL Pose {
            rotation 0.577656895078166 0.5771968951617173 -0.5771968951617173 -2.093935
            children [
              Shape {
                appearance PBRAppearance {
                  baseColor 0.0037037 0.0037037 0.0037037
                  roughness 0.3
                  metalness 0
                }
                geometry Cylinder {
                  height 0.037
                  radius 0.0825
                }
              }
            ]
          }
        ]
        name "left wheel"
        boundingObject USE WHEEL
      }
    }
    HingeJoint {
      jointParameters HingeJointParameters {
        axis 0 1 0
        anchor 0 0 0.0825
      }
      device [
        RotationalMotor {
          name "right wheel motor"
        }
        PositionSensor {
          name "right wheel sensor"
        }
      ]
      endPoint Solid {
        translation 0 -0.1603 0.0825
        rotation 0.6879677669702214 -0.6879677669702214 -0.23108592172612766 2.687394
        children [
          USE WHEEL
        ]
        name "right wheel"
        boundingObject USE WHEEL
      }
    }
    Shape {
      appearance PBRAppearance {
        baseColor 1 0 0
        roughness 0.3
        metalness 0
      }
      geometry IndexedFaceSet {
        coord Coordinate {
          point [
            0.046 -0.136 0.184
            0.096 -0.136 0.184
            0.134 -0.101 0.184
            0.159 -0.054 0.184
            0.168 0 0.184
            0.159 0.054 0.184
            0.134 0.101 0.184
            0.096 0.136 0.184
            0.046 0.136 0.184
            0.043 -0.136 0.184
            0.046 -0.136 0.234
            0.096 -0.136 0.234
            0.134 -0.101 0.234
            0.159 -0.054 0.234
            0.168 0 0.234
            0.159 0.054 0.234
            0.134 0.101 0.234
            0.096 0.136 0.234
            0.046 0.136 0.234
            0.043 -0.136 0.234
          ]
        }
        coordIndex [
          9, 8, 7, 6, 5, 4, 3, 2, 1, 0, -1, 10, 11, 12, 13, 14, 15, 16, 17, 18, 19, -1, 0, 1, 11, 10, -1, 1, 2, 12, 11, -1, 2, 3, 13, 12, -1, 3, 4, 14, 13, -1, 4, 5, 15, 14, -1, 5, 6, 16, 15, -1, 6, 7, 17, 16, -1, 7, 8, 18, 17, -1, 8, 9, 19, 18, -1, 9, 0, 10, 19, -1
        ]
      }
    }
    Shape {
      appearance PBRAppearance {
        baseColor 1 0 0
        roughness 0.3
        metalness 0
      }
      geometry IndexedFaceSet {
        coord Coordinate {
          point [
            -0.135 0.136 0.184
            -0.185 0.136 0.184
            -0.223 0.101 0.184
            -0.248 0.054 0.184
            -0.257 0 0.184
            -0.248 -0.054 0.184
            -0.223 -0.101 0.184
            -0.185 -0.136 0.184
            -0.135 -0.136 0.184
            -0.135 0.136 0.184
            -0.135 0.136 0.234
            -0.185 0.136 0.234
            -0.223 0.101 0.234
            -0.248 0.054 0.234
            -0.257 0 0.234
            -0.248 -0.054 0.234
            -0.223 -0.101 0.234
            -0.185 -0.136 0.234
            -0.135 -0.136 0.234
            -0.135 0.136 0.234
          ]
        }
        coordIndex [
          9, 8, 7, 6, 5, 4, 3, 2, 1, 0, -1, 10, 11, 12, 13, 14, 15, 16, 17, 18, 19, -1, 0, 1, 11, 10, -1, 1, 2, 12, 11, -1, 2, 3, 13, 12, -1, 3, 4, 14, 13, -1, 4, 5, 15, 14, -1, 5, 6, 16, 15, -1, 6, 7, 17, 16, -1, 7, 8, 18, 17, -1, 8, 9, 19, 18, -1
        ]
      }
    }
    Pose {
      translation -0.2147 0 0.0325
      rotation 0.5771968951617173 0.5771968951617173 0.577656895078166 -2.093935
      children [
        Shape {
          appearance PBRAppearance {
            baseColor 0.0037037 0.0037037 0.0037037
            roughness 0.3
            metalness 0
          }
          geometry Cylinder {
            height 0.024
            radius 0.0325
          }
        }
      ]
    }
    DistanceSensor {
      translation 0.116 0.118 0.209
      rotation 0.8349694730900802 0.38911822047269523 0.38911822047269523 1.750187
      children [
        DEF SONAR Pose {
          rotation 0.577656895078166 0.5771968951617173 -0.5771968951617173 -2.093935
          children [
            Shape {
              appearance PBRAppearance {
                baseColor 1 1 0.0517103
                roughness 0.3
                metalness 0
              }
              geometry Cylinder {
                height 0.002
                radius 0.0175
              }
            }
          ]
        }
      ]
      name "ds0"
      lookupTable [
        0 1024 0
        0.2 1024 0.1
        0.4 0 0.1
      ]
      type "sonar"
      numberOfRays 5
    }
    DistanceSensor {
      translation 0.169 0 0.209
      rotation 1 0 0 1.5708
      children [
        USE SONAR
      ]
      name "ds1"
      lookupTable [
        0 1024 0
        0.2 1024 0.1
        0.4 0 0.1
      ]
      type "sonar"
      numberOfRays 5
    }
    DistanceSensor {
      translation 0.116 -0.118 0.209
      rotation 0.8347739105773538 -0.38932795829441263 -0.38932795829441263 1.750417
      children [
        USE SONAR
      ]
      name "ds2"
      lookupTable [
        0 1024 0
        0.2 1024 0.1
        0.4 0 0.1
      ]
      type "sonar"
      numberOfRays 5
    }
    DistanceSensor {
      translation -0.205 0.118 0.209
      rotation -0.31297577647997865 -0.6715825203713816 -0.6715825203713816 -2.534956
      children [
        USE SONAR
      ]
      name "ds3"
      lookupTable [
        0 1024 0
        0.2 1024 0.1
        0.4 0 0.1
      ]
      type "sonar"
      numberOfRays 5
    }
    DistanceSensor {
      translation -0.257 0 0.209
      rotation 0 0.7071067811865476 0.7071067811865476 -3.14159
      children [
        USE SONAR
      ]
      name "ds4"
      lookupTable [
        0 1024 0
        0.2 1024 0.1
        0.4 0 0.1
      ]
      type "sonar"
      numberOfRays 5
    }
    DistanceSensor {
      translation -0.205 -0.118 0.209
      rotation -0.31319385347479545 0.6715316858293465 0.6715316858293465 -2.534558
      children [
        USE SONAR
      ]
      name "ds5"
      lookupTable [
        0 1024 0
        0.2 1024 0.1
        0.4 0 0.1
      ]
      type "sonar"
      numberOfRays 5
    }
  ]
  name "Pioneer 2(3)"
  description "designed by Activmedia Robotics"
  boundingObject Pose {
    translation -0.0447 0 0.13
    rotation 0 0 1 -1.570796
    children [
      Cylinder {
        height 0.24
        radius 0.219
      }
    ]
  }
  controller "<none>"
}
DEF PIONEER2 Robot {
  translation 0 -0.1 0
  rotation 0 0 1 -1.5707953071795862
  children [
    Group {
    }
    Shape {
      appearance PBRAppearance {
        baseColor 1 0 0
        roughness 0.3
        metalness 0
      }
      geometry IndexedFaceSet {
        coord Coordinate {
          point [
            -0.215 0.1 0.059
            -0.215 -0.1 0.059
            -0.185 -0.135 0.059
            0.095 -0.135 0.059
            0.11 -0.08 0.059
            0.11 0.08 0.059
            0.095 0.135 0.059
            -0.185 0.135 0.059
            -0.215 0.1 0.059
            -0.215 0.1 0.234
            -0.215 -0.1 0.234
            -0.185 -0.135 0.234
            0.095 -0.135 0.234
            0.11 -0.08 0.234
            0.11 0.08 0.234
            0.095 0.135 0.234
            -0.185 0.135 0.234
            -0.215 0.1 0.234
          ]
        }
        coordIndex [
          8, 7, 6, 5, 4, 3, 2, 1, 0, -1, 9, 10, 11, 12, 13, 14, 15, 16, 17, -1, 0, 1, 10, 9, -1, 1, 2, 11, 10, -1, 2, 3, 12, 11, -1, 3, 4, 13, 12, -1, 4, 5, 14, 13, -1, 5, 6, 15, 14, -1, 6, 7, 16, 15, -1, 7, 8, 17, 16, -1
        ]
      }
    }
    HingeJoint {
      jointParameters HingeJointParameters {
        axis 0 1 0
        anchor 0 0 0.0825
      }
      device [
        RotationalMotor {
          name "left wheel motor"
        }
        PositionSensor {
          name "left wheel sensor"
        }
      ]
      endPoint Solid {
        translation 0 0.1603 0.0825
        rotation -0.25268397011342625 0.25268397011342625 0.9339708895331987 -1.639053
        children [
          DEF WHEEL Pose {
            rotation 0.577656895078166 0.5771968951617173 -0.5771968951617173 -2.093935
            children [
              Shape {
                appearance PBRAppearance {
                  baseColor 0.0037037 0.0037037 0.0037037
                  roughness 0.3
                  metalness 0
                }
                geometry Cylinder {
                  height 0.037
                  radius 0.0825
                }
              }
            ]
          }
        ]
        name "left wheel"
        boundingObject USE WHEEL
      }
    }
    HingeJoint {
      jointParameters HingeJointParameters {
        axis 0 1 0
        anchor 0 0 0.0825
      }
      device [
        RotationalMotor {
          name "right wheel motor"
        }
        PositionSensor {
          name "right wheel sensor"
        }
      ]
      endPoint Solid {
        translation 0 -0.1603 0.0825
        rotation 0.6879677669702214 -0.6879677669702214 -0.23108592172612766 2.687394
        children [
          USE WHEEL
        ]
        name "right wheel"
        boundingObject USE WHEEL
      }
    }
    Shape {
      appearance PBRAppearance {
        baseColor 1 0 0
        roughness 0.3
        metalness 0
      }
      geometry IndexedFaceSet {
        coord Coordinate {
          point [
            0.046 -0.136 0.184
            0.096 -0.136 0.184
            0.134 -0.101 0.184
            0.159 -0.054 0.184
            0.168 0 0.184
            0.159 0.054 0.184
            0.134 0.101 0.184
            0.096 0.136 0.184
            0.046 0.136 0.184
            0.043 -0.136 0.184
            0.046 -0.136 0.234
            0.096 -0.136 0.234
            0.134 -0.101 0.234
            0.159 -0.054 0.234
            0.168 0 0.234
            0.159 0.054 0.234
            0.134 0.101 0.234
            0.096 0.136 0.234
            0.046 0.136 0.234
            0.043 -0.136 0.234
          ]
        }
        coordIndex [
          9, 8, 7, 6, 5, 4, 3, 2, 1, 0, -1, 10, 11, 12, 13, 14, 15, 16, 17, 18, 19, -1, 0, 1, 11, 10, -1, 1, 2, 12, 11, -1, 2, 3, 13, 12, -1, 3, 4, 14, 13, -1, 4, 5, 15, 14, -1, 5, 6, 16, 15, -1, 6, 7, 17, 16, -1, 7, 8, 18, 17, -1, 8, 9, 19, 18, -1, 9, 0, 10, 19, -1
        ]
      }
    }
    Shape {
      appearance PBRAppearance {
        baseColor 1 0 0
        roughness 0.3
        metalness 0
      }
      geometry IndexedFaceSet {
        coord Coordinate {
          point [
            -0.135 0.136 0.184
            -0.185 0.136 0.184
            -0.223 0.101 0.184
            -0.248 0.054 0.184
            -0.257 0 0.184
            -0.248 -0.054 0.184
            -0.223 -0.101 0.184
            -0.185 -0.136 0.184
            -0.135 -0.136 0.184
            -0.135 0.136 0.184
            -0.135 0.136 0.234
            -0.185 0.136 0.234
            -0.223 0.101 0.234
            -0.248 0.054 0.234
            -0.257 0 0.234
            -0.248 -0.054 0.234
            -0.223 -0.101 0.234
            -0.185 -0.136 0.234
            -0.135 -0.136 0.234
            -0.135 0.136 0.234
          ]
        }
        coordIndex [
          9, 8, 7, 6, 5, 4, 3, 2, 1, 0, -1, 10, 11, 12, 13, 14, 15, 16, 17, 18, 19, -1, 0, 1, 11, 10, -1, 1, 2, 12, 11, -1, 2, 3, 13, 12, -1, 3, 4, 14, 13, -1, 4, 5, 15, 14, -1, 5, 6, 16, 15, -1, 6, 7, 17, 16, -1, 7, 8, 18, 17, -1, 8, 9, 19, 18, -1
        ]
      }
    }
    Pose {
      translation -0.2147 0 0.0325
      rotation 0.5771968951617173 0.5771968951617173 0.577656895078166 -2.093935
      children [
        Shape {
          appearance PBRAppearance {
            baseColor 0.0037037 0.0037037 0.0037037
            roughness 0.3
            metalness 0
          }
          geometry Cylinder {
            height 0.024
            radius 0.0325
          }
        }
      ]
    }
    DistanceSensor {
      translation 0.071 0.136 0.209
      rotation 0.5779627730800116 0.5770437734408297 0.5770437734408297 2.093476
      children [
        DEF SONAR Pose {
          rotation 0.577656895078166 0.5771968951617173 -0.5771968951617173 -2.093935
          children [
            Shape {
              appearance PBRAppearance {
                baseColor 1 1 0.0517103
                roughness 0.3
                metalness 0
              }
              geometry Cylinder {
                height 0.002
                radius 0.0175
              }
            }
          ]
        }
      ]
      name "ds0"
      lookupTable [
        0 1024 0
        0.2 1024 0.1
        0.4 0 0.1
      ]
      type "sonar"
      numberOfRays 5
    }
    DistanceSensor {
      translation -0.049 0.136192 0.209
      rotation 0.5779627730800116 0.5770437734408297 0.5770437734408297 2.093476
      children [
        USE SONAR
      ]
      name "ds1"
      lookupTable [
        0 1024 0
        0.2 1024 0.1
        0.4 0 0.1
      ]
      type "sonar"
      numberOfRays 5
    }
    DistanceSensor {
      translation 0.071 -0.136 0.209
      rotation 0.5773502691896258 -0.5773502691896258 -0.5773502691896258 2.094395
      children [
        USE SONAR
      ]
      name "ds2"
      lookupTable [
        0 1024 0
        0.2 1024 0.1
        0.4 0 0.1
      ]
      type "sonar"
      numberOfRays 5
    }
    DistanceSensor {
      translation -0.16 0.136 0.209
      rotation -0.5767367732078247 -0.5776567728460501 -0.5776567728460501 -2.095315
      children [
        USE SONAR
      ]
      name "ds3"
      lookupTable [
        0 1024 0
        0.2 1024 0.1
        0.4 0 0.1
      ]
      type "sonar"
      numberOfRays 5
    }
    DistanceSensor {
      translation -0.06 -0.136 0.209
      rotation 0.5773502691896258 -0.5773502691896258 -0.5773502691896258 2.094395
      children [
        USE SONAR
      ]
      name "ds4"
      lookupTable [
        0 1024 0
        0.2 1024 0.1
        0.4 0 0.1
      ]
      type "sonar"
      numberOfRays 5
    }
    DistanceSensor {
      translation -0.16 -0.136 0.209
      rotation 0.5773502691896258 -0.5773502691896258 -0.5773502691896258 2.094395
      children [
        USE SONAR
      ]
      name "ds5"
      lookupTable [
        0 1024 0
        0.2 1024 0.1
        0.4 0 0.1
      ]
      type "sonar"
      numberOfRays 5
    }
  ]
  name "Pioneer 2(4)"
  description "designed by Activmedia Robotics"
  boundingObject Pose {
    translation -0.0447 0 0.13
    rotation 0 0 1 -1.570796
    children [
      Cylinder {
        height 0.24
        radius 0.219
      }
    ]
  }
  controller "<none>"
}
