#VRML_SIM R2023b utf8
# license: Copyright Cyberbotics Ltd. Licensed for use only with Webots.
# license url: https://cyberbotics.com/webots_assets_license
# documentation url: https://webots.cloud/run?url=https://github.com/cyberbotics/webots/blob/released/projects/robots/adept/pioneer2/protos/Pioneer2.proto
# keywords: robot/wheeled
# The Pioneer 2 robot (Adept MobileRobots) is an all-purpose base, used for research and applications involving mapping, teleoperation, localization, monitoring, reconnaissance and other behaviors.

PROTO Pioneer2Robot [
  field SFVec3f    translation     1 1 1         # Is `Transform.translation`.
  field SFRotation rotation        0 0 1 0       # Is `Transform.rotation`.
  field SFString   name            "Pioneer 2"   # Is `Solid.name`.
  field SFString   controller      "<none>"      # Is `Robot.controller`.
  field MFString   controllerArgs  []            # Is `Robot.controllerArgs`.
  field SFString   window          "<generic>"   # Is `Robot.window`.
  field SFString   customData      ""            # Is `Robot.customData`.
  field SFBool     supervisor      FALSE         # Is `Robot.supervisor`.
  field SFBool     synchronization TRUE          # Is `Robot.synchronization`.
  field MFNode     extensionSlot   []            # Extends the robot with new nodes in the extension slot.
  field SFColor    color           0.75 1 0.75   # The color of the robot.
]
{
  DEF PIONEER2 Robot {
    translation IS translation
    rotation IS rotation
    controller IS controller
    controllerArgs IS controllerArgs
    window IS window
    customData IS customData
    supervisor IS supervisor
    synchronization IS synchronization
    name IS name
    children [
      Group {
        children IS extensionSlot
      }
      Shape {
        appearance PBRAppearance {
          baseColor IS color
          metalness 0
          roughness 0.3
        }
        geometry IndexedFaceSet {
          coord Coordinate {
            point [
              -0.215 0.1 0.059 -0.215 -0.1 0.059 -0.185 -0.135 0.059 0.095 -0.135 0.059 0.11 -0.08 0.059 0.11 0.08 0.059 0.095 0.135 0.059 -0.185 0.135 0.059 -0.215 0.1 0.059 -0.215 0.1 0.234 -0.215 -0.1 0.234 -0.185 -0.135 0.234 0.095 -0.135 0.234 0.11 -0.08 0.234 0.11 0.08 0.234 0.095 0.135 0.234 -0.185 0.135 0.234 -0.215 0.1 0.234
            ]
          }
          coordIndex [
            8, 7, 6, 5, 4, 3, 2, 1, 0, -1, 9, 10, 11, 12, 13, 14, 15, 16, 17, -1, 0, 1, 10, 9, -1, 1, 2, 11, 10, -1, 2, 3, 12, 11, -1, 3, 4, 13, 12, -1, 4, 5, 14, 13, -1, 5, 6, 15, 14, -1, 6, 7, 16, 15, -1, 7, 8, 17, 16, -1
          ]
        }
      }
      HingeJoint {
        jointParameters HingeJointParameters {
          axis 0 1 0
          anchor 0 0 0.0825
        }
        device [
          RotationalMotor {
            name "left wheel motor"
          }
          PositionSensor {
            name "left wheel sensor"
          }
        ]
        endPoint Solid {
          translation 0 0.1603 0.0825
          rotation -0.252684 0.252684 0.933971 -1.639053
          children [
            DEF WHEEL Pose {
              rotation 0.577657 0.577197 -0.577197 -2.093935
              children [
                Shape {
                  appearance PBRAppearance {
                    baseColor 0.0037037 0.0037037 0.0037037
                    metalness 0
                    roughness 0.3
                  }
                  geometry Cylinder {
                    height 0.037
                    radius 0.0825
                  }
                }
              ]
            }
          ]
          name "left wheel"
          boundingObject USE WHEEL
        }
      }
      HingeJoint {
        jointParameters HingeJointParameters {
          axis 0 1 0
          anchor 0 0 0.0825
        }
        device [
          RotationalMotor {
            name "right wheel motor"
          }
          PositionSensor {
            name "right wheel sensor"
          }
        ]
        endPoint Solid {
          translation 0 -0.1603 0.0825
          rotation 0.687968 -0.687968 -0.231086 2.687394
          children [
            USE WHEEL
          ]
          name "right wheel"
          boundingObject USE WHEEL
        }
      }
      Shape {
        appearance PBRAppearance {
          baseColor IS color
          metalness 0
          roughness 0.3
        }
        geometry IndexedFaceSet {
          coord Coordinate {
            point [
              0.046 -0.136 0.184 0.096 -0.136 0.184 0.134 -0.101 0.184 0.159 -0.054 0.184 0.168 0 0.184 0.159 0.054 0.184 0.134 0.101 0.184 0.096 0.136 0.184 0.046 0.136 0.184 0.043 -0.136 0.184 0.046 -0.136 0.234 0.096 -0.136 0.234 0.134 -0.101 0.234 0.159 -0.054 0.234 0.168 0 0.234 0.159 0.054 0.234 0.134 0.101 0.234 0.096 0.136 0.234 0.046 0.136 0.234 0.043 -0.136 0.234
            ]
          }
          coordIndex [
            9, 8, 7, 6, 5, 4, 3, 2, 1, 0, -1, 10, 11, 12, 13, 14, 15, 16, 17, 18, 19, -1, 0, 1, 11, 10, -1, 1, 2, 12, 11, -1, 2, 3, 13, 12, -1, 3, 4, 14, 13, -1, 4, 5, 15, 14, -1, 5, 6, 16, 15, -1, 6, 7, 17, 16, -1, 7, 8, 18, 17, -1, 8, 9, 19, 18, -1, 9, 0, 10, 19, -1
          ]
        }
      }
      Shape {
        appearance PBRAppearance {
          baseColor IS color
          metalness 0
          roughness 0.3
        }
        geometry IndexedFaceSet {
          coord Coordinate {
            point [
              -0.135 0.136 0.184 -0.185 0.136 0.184 -0.223 0.101 0.184 -0.248 0.054 0.184 -0.257 0 0.184 -0.248 -0.054 0.184 -0.223 -0.101 0.184 -0.185 -0.136 0.184 -0.135 -0.136 0.184 -0.135 0.136 0.184 -0.135 0.136 0.234 -0.185 0.136 0.234 -0.223 0.101 0.234 -0.248 0.054 0.234 -0.257 0 0.234 -0.248 -0.054 0.234 -0.223 -0.101 0.234 -0.185 -0.136 0.234 -0.135 -0.136 0.234 -0.135 0.136 0.234
            ]
          }
          coordIndex [
            9, 8, 7, 6, 5, 4, 3, 2, 1, 0, -1, 10, 11, 12, 13, 14, 15, 16, 17, 18, 19, -1, 0, 1, 11, 10, -1, 1, 2, 12, 11, -1, 2, 3, 13, 12, -1, 3, 4, 14, 13, -1, 4, 5, 15, 14, -1, 5, 6, 16, 15, -1, 6, 7, 17, 16, -1, 7, 8, 18, 17, -1, 8, 9, 19, 18, -1
          ]
        }
      }
      Pose {
        translation -0.2147 0 0.0325
        rotation 0.577197 0.577197 0.577657 -2.093935
        children [
          Shape {
            appearance PBRAppearance {
              baseColor 0.0037037 0.0037037 0.0037037
              metalness 0
              roughness 0.3
            }
            geometry Cylinder {
              height 0.024
              radius 0.0325
            }
          }
        ]
      }
      DistanceSensor {
        translation 0.164 0.027 0.209
        rotation 0 0 1 0.174203
        children [
          DEF SONAR Pose {
            rotation 0.577657 0.577197 -0.577197 -2.093935
            children [
              Shape {
                appearance PBRAppearance {
                  baseColor 1 1 0.0517103
                  metalness 0
                  roughness 0.3
                }
                geometry Cylinder {
                  height 0.002
                  radius 0.0175
                }
              }
            ]
          }
        ]
        name "ds0"
        lookupTable [
          0 1024 0 0.2 1024 0.1 0.4 0 0.1
        ]
        type "sonar"
      }
      DistanceSensor {
        translation 0.147 0.077 0.209
        rotation 0.935206 0.25039 0.25039 1.637735
        children [
          USE SONAR
        ]
        name "ds1"
        lookupTable [
          0 1024 0 0.2 1024 0.1 0.4 0 0.1
        ]
        type "sonar"
      }
      DistanceSensor {
        translation 0.116 0.118 0.209
        rotation 0.834969 0.389118 0.389118 1.750187
        children [
          USE SONAR
        ]
        name "ds2"
        lookupTable [
          0 1024 0 0.2 1024 0.1 0.4 0 0.1
        ]
        type "sonar"
      }
      DistanceSensor {
        translation 0.071 0.136 0.209
        rotation 0.577963 0.577044 0.577044 2.093476
        children [
          USE SONAR
        ]
        name "ds3"
        lookupTable [
          0 1024 0 0.2 1024 0.1 0.4 0 0.1
        ]
        type "sonar"
      }
      DistanceSensor {
        translation 0.071 -0.136 0.209
        rotation 0.57735 -0.57735 -0.57735 2.094395
        children [
          USE SONAR
        ]
        name "ds12"
        lookupTable [
          0 1024 0 0.2 1024 0.1 0.4 0 0.1
        ]
        type "sonar"
      }
      DistanceSensor {
        translation 0.116 -0.118 0.209
        rotation 0.834774 -0.389328 -0.389328 1.750417
        children [
          USE SONAR
        ]
        name "ds13"
        lookupTable [
          0 1024 0 0.2 1024 0.1 0.4 0 0.1
        ]
        type "sonar"
      }
      DistanceSensor {
        translation 0.147 -0.077 0.209
        rotation 0.935067 -0.250649 -0.250649 1.637883
        children [
          USE SONAR
        ]
        name "ds14"
        lookupTable [
          0 1024 0 0.2 1024 0.1 0.4 0 0.1
        ]
        type "sonar"
      }
      DistanceSensor {
        translation 0.164 -0.027 0.209
        rotation -0.99241 0.086956 0.086956 -1.578415
        children [
          USE SONAR
        ]
        name "ds15"
        lookupTable [
          0 1024 0 0.2 1024 0.1 0.4 0 0.1
        ]
        type "sonar"
      }
    ]
    description "designed by Activmedia Robotics"
    boundingObject Pose {
      translation -0.0447 0 0.13
      rotation 0 0 1 -1.570796
      children [
        Cylinder {
          height 0.24
          radius 0.219
        }
      ]
    }
  }
}